Workbook

Sheet 00 - Read Me First
A1: Rivet x Crewline - Full Market Study & End-to-End Gap Analysis
A2: What exists today (verified in code + on the live site), where it lags the market, and exactly what turns it into a full-fledged startup. July 6, 2026.
A4: How to read this | B4: Start with 01a (master comparison, one capability per row). 01b totals it. 02 defines the Three Rings. 03 profiles competitors. 04 is the evidence log of everything built so far. 05 sizes the market. 06 is the sprint-by-sprint roadmap. 07 is risks.
A5: Status legend | B5: AHEAD (green) = better than typical market leaders. PARITY (yellow) = at par. PARTIAL (orange) = shipped but incomplete. BEHIND (red) = not shipped.
A6: Gap legend | B6: Critical = blocks trust, revenue, or launch. High = blocks scale. Medium = competitive drag. Small = polish. None = no gap.
A7: Method | B7: Product facts verified directly: code inspection, local end-to-end tests, and live probes of rivet-crewline.onrender.com (healthz diagnostics, signup flows). Nothing here is guessed.
A8: Market data caveat | B8: Key figures verified via live web search on Jul 6, 2026: Instawork ($160M raised, 4M+ workers), Traba ($43.6M raised), ABC construction shortage (439,000 workers, 2025; 2026 projections range 350-500k). Remaining competitor figures are early-2026 knowledge - tab 08 lists every source and what is verified vs pending.
A9: The one-line verdict | B9: UPDATED Jul 7: Ring 1 is ~90% done (email delivery now live). Ring 2 moved from ~25% to ~35% this week: credential review pipeline, admin panel, legal pages, account deletion all shipped. The remaining Critical gaps are business-side: payments (Stripe), background checks (Checkr), real users in one metro, and counsel-reviewed legal. Weighted readiness ~55%.

Sheet 01a - Rivet vs Market
A1: 01a - Rivet x Crewline vs Market: the master comparison across every meaningful capability
A2: Read top-to-bottom. Each row is one capability. We name the market leader, score Rivet against them, name the gap, and name the action. No hand-waving.
A4: Capability | B4: Ring | C4: Rivet status | D4: Rivet detail (Jul 2026) | E4: Market leader | F4: What the leader ships | G4: Gap size | H4: Action / horizon
A5: RING 1 - CORE MARKETPLACE: can a worker and an employer actually use it? (verdict: ~85% done, several genuinely ahead-of-market pieces)
A6: Email/password auth | B6: Ring 1 | C6: Parity | D6: scrypt-hashed passwords, signed HttpOnly session cookies, login lockout (10 fails / 15 min / IP+email). Live. | E6: Everyone | F6: Table stakes. | G6: None | H6: Done. Maintain.
A7: Email OTP verification at signup | B7: Ring 1 | C7: Parity | D7: DONE & LIVE (Jul 7): codes deliver via Brevo HTTPS API (Render firewalls SMTP - diagnosed and engineered around: dual-port self-heal + automatic API fallback). Enforced: no unverified account reaches the app. | E7: Indeed Flex, Instawork | F7: Verified contact at onboarding. | G7: None | H7: Done. Monitor Brevo quota (300/day free).
A8: Google sign-in | B8: Ring 1 | C8: Parity | D8: Live and verified on production (button renders, creds detected). Google-verified emails skip OTP. | E8: Everyone | F8: OAuth SSO. | G8: None | H8: Done.
A9: Phone / SMS OTP login | B9: Ring 1 | C9: Partial | D9: Twilio wired + detected on prod; login field accepts email OR mobile; rate-capped (3/hr/number). Twilio TRIAL account only texts verified numbers. | E9: Instawork, Wonolo | F9: Phone-first onboarding (their workers live on phones). | G9: Small | H9: Upgrade Twilio (~$1/mo + usage) at first real users. Day 0-30.
A10: Worker profile ("Work Card") | B10: Ring 1 | C10: Parity | D10: Multi-trade, headline/about (AI-drafted via Groq with $0 fallback), work history, portfolio media, skill checks, availability toggles, veteran/tools/transport flags. | E10: Instawork | F10: Rich worker profile w/ reliability stats. | G10: Small | H10: Polish; add profile completeness meter. 30d.
A11: Conversational onboarding | B11: Ring 1 | C11: Ahead | D11: Chat-style onboarding alternative + AI-drafted About. Few competitors ship this. | E11: - | F11: - | G11: None | H11: Keep. Quiet differentiator.
A12: Matching engine | B12: Ring 1 | C12: Ahead | D12: Live-computed scores: trade fit + adjacency, pay vs worker floor, distance tiers, verified-credential coverage; readiness score; weights in one file; 8 unit tests green. | E12: Instawork | F12: ML shift-fill ranking at scale. | G12: Small | H12: Add outcome feedback loop (hires retrain weights). 90d.
A13: Real live job supply | B13: Ring 1 | C13: Ahead | D13: 4,800-6,700 REAL jobs ingested from ~40 public employer ATS feeds (Workday, Lever, Ashby, SmartRecruiters) with dedupe, freshness pruning, pay normalization, trade retagging. Self-refreshes every 6h. This is real, not seeded. | E13: Indeed (aggregation giant) | F13: Massive aggregation + employer network. | G13: Medium vs Indeed; AHEAD vs staffing apps | H13: Add employer claim-your-job flow -> converts supply into paying customers. 60-90d.
A14: Job detail w/ score transparency | B14: Ring 1 | C14: Ahead | D14: Shows WHY matched (per-factor breakdown), pay vs local market percentile, employer trust card (pay-on-time, safety, rehire rate). | E14: - | F14: Opaque matching everywhere else. | G14: None | H14: Keep. Trust = the brand.
A15: One-tap apply + tracker | B15: Ring 1 | C15: Parity | D15: Apply -> employer notified in-app; worker kanban tracker; SMS status alerts (when Twilio live). | E15: Everyone | F15: - | G15: None | H15: Done.
A16: In-app messaging | B16: Ring 1 | C16: Parity | D16: Worker <-> employer threads, unread badges, read receipts, quote messages. | E16: Everyone | F16: - | G16: None | H16: Done.
A17: Employer console (overview) | B17: Ring 1 | C17: Parity | D17: KPIs, funnel, hot candidates, alerts, fill-rate. | E17: Traba, Instawork | F17: Ops dashboards. | G17: Small | H17: Done for MVP.
... A28: Responsive web (PWA-ready) | B28: Ring 1 | C28: Parity | D28: Fully responsive + INSTALLABLE (Jul 6): manifest + service worker + icon - "Add to Home Screen" works. Site-wide polish: page transitions, nav progress bar, button loading spinners, scroll reveals (reduced-motion respected). | E28: - | F28: - | G28: None | H28: Done. Native wrapper (Capacitor) remains the 90d item.
A29: RING 2 - TRUST & MONEY: what makes it a real business. (verdict: ~25% done - every Critical gap in this study lives here)
A30: CREDENTIAL VERIFICATION (the moat) | B30: Ring 2 | C30: Partial | D30: V1 LIVE (Jul 6): worker submits proof (phone-camera photo or link) -> credential goes IN REVIEW -> human approves/rejects in /admin -> only then the Verified badge, which drives real match scores. Demo self-verify removed. NOT yet: state-board lookups, automation. | E30: Checkr Trust, Evident; BlueRecruit (manual) | F30: Real license/cert verification against issuers. | G30: High (scale) | H30: Sprint: state-board web lookups (AZ ROC, EPA 608). Automate top-10 creds by 90d.
A31: Background checks | B31: Ring 2 | C31: Behind | D31: None. | E31: Instawork, Wonolo, Traba (via Checkr/Turn) | F31: Integrated BGC at onboarding; employers filter by it. | G31: Critical (employer trust) | H31: Checkr sandbox integration + consent flow. 30-60d.
A32: Worker payouts / instant pay | B32: Ring 2 | C32: Behind | D32: Pay-cadence metadata only; no money moves. Instant pay is THE retention lever for shift workers. | E32: Instawork (InstantPay), Traba (next-day) | F32: Wallet + instant payout (Stripe Connect / Branch). | G32: Critical (revenue + retention) | H32: Stripe Connect Express pilot on shift claims, one metro. 60-90d.
A33: Employer billing / take-rate | B33: Ring 2 | C33: Behind | D33: No monetization at all today. | E33: Instawork/Traba: 25-40% markup on shifts; ATS: SaaS | F33: Clear pricing engine. | G33: Critical (revenue) | H33: Decide: % on shifts + placement fee on direct hire + free ATS. Stripe invoicing. 60-90d.
A34: Worker classification (W-2 / 1099) | B34: Ring 2 | C34: Behind | D34: N/A - no paid work yet. Every US shift marketplace lives or dies here (Wonolo lawsuits; Instawork ships W-2 option). | E34: Instawork, Bluecrew (W-2) | F34: Classification engine + payroll partner. | G34: Critical (before scaling shifts) | H34: Legal counsel + payroll partner (Check, Zeal) decision by 6mo.
A35: Occupational insurance | B35: Ring 2 | C35: Behind | D35: None. Required to onboard serious employers for shifts. | E35: Instawork, Wonolo | F35: Occ-accident / GL cover bundled. | G35: High | H35: Broker after classification decision. 6mo.
A36: Two-sided reputation | B36: Ring 2 | C36: Ahead | D36: UNIQUE combo live: worker Show-Up Score, employer Paid-Like-Promised %, site Safety Pulse, rehire-rate badge, two-sided star reviews tied to real jobs. | E36: Traba (worker reliability only) | F36: One-sided ratings. | G36: None | H36: Keep - this is a trust moat in embryo. Market it.
A37: Real file uploads | B37: Ring 2 | C37: Partial | D37: Credential proofs now upload as phone-camera photos (size-capped, stored in DB, served to admin only). Portfolio media still URL-based. | E37: Everyone | F37: Direct upload (S3-class). | G37: Small | H37: Move to Cloudflare R2 presigned uploads when volume grows. 60d.
A38: Notifications (push/email) | B38: Ring 2 | C38: Behind | D38: SMS hooks exist (Twilio-gated). No web push, no email digests. | E38: Mobile apps of all leaders | F38: Push is how shift fills happen in minutes. | G38: High | H38: Web Push (VAPID) + daily digest emails. 30-60d.
A39: Native mobile apps | B39: Ring 2 | C39: Behind | D39: Responsive web only. Workers are mobile-first; retention needs an icon on their phone. | E39: Instawork, Wonolo, Traba | F39: Polished iOS/Android apps. | G39: High (not urgent Day 0) | H39: PWA manifest now; Capacitor wrapper 90d; native only after traction.
A40: Admin / ops panel | B40: Ring 2 | C40: Parity | D40: LIVE (Jul 6): /admin gated by ADMIN_EMAILS - credential review queue with proof viewer, user search, job moderation (close), platform stats. Verified on production. | E40: Internal tools everywhere | F40: User lookup, credential review queue, job moderation, refunds. | G40: None | H40: Done for this stage. Add "delete user" + audit log when ops volume grows.
A41: Anti-fraud / abuse | B41: Ring 2 | C41: Partial | D41: Shipped this week: login lockout, OTP attempt caps (5 tries kills code), resend throttles, signup caps (20/hr/IP), SMS caps (3/hr/number). No device fingerprinting / ML. | E41: Leaders (ML + device signals) | F41: Fraud scoring at scale. | G41: Medium | H41: Fine for launch; revisit at 10k users.
A42: Legal: ToS, Privacy, EEOC posture | B42: Ring 2 | C42: Partial | D42: SHIPPED (Jul 6): /terms, /privacy, /eeo pages linked in footers + full GDPR-style account deletion (cascades all user data; tested). Templates are honest but NOT counsel-reviewed. | E42: Table stakes | F42: ToS, Privacy Policy, EEO statement, data deletion. | G42: Medium | H42: Counsel review (~$500) before scale; W-2/1099 opinion before first paid shift.
A43: RING 3 - SCALE & MOAT: what makes it a company. (verdict: ~20% done - correct for this stage; do not build these before Ring 2)
A44: Liquidity strategy (chicken & egg) | B44: Ring 3 | C44: Behind | D44: Real demand exists (live jobs) but worker supply is demo-seeded. No live metro. | E44: Instawork (6M+ workers) | F44: Density city-by-city. | G44: Critical (the startup problem) | H44: Pick Phoenix + semiconductor/manufacturing vertical (app already targets it). 90d goal: 200 verified workers, 10 paying employers.
A45: Employer ATS write-back | B45: Ring 3 | C45: Behind | D45: Ingestion is read-only; applies to external jobs deep-link out. | E45: Merge.dev-class integrations | F45: Two-way ATS sync. | G45: Medium | H45: Only after employer traction. 6mo+.
A46: Employer analytics | B46: Ring 3 | C46: Partial | D46: Funnel, time-to-fill, 8-week trend analytics live on console. | E46: Traba | F46: Deeper ops dashboards. | G46: Small | H46: Good enough. Iterate with customers.
A47: Public API / partners | B47: Ring 3 | C47: Behind | D47: None. | E47: - | F47: - | G47: Low | H47: Post-traction.
A48: SEO / programmatic pages | B48: Ring 3 | C48: Partial | D48: Public job pages, sitemap.xml, OG images, sectors + careers pages exist. No per-metro/per-trade landing factory. | E48: Indeed (SEO empire) | F48: Thousands of indexed landing pages. | G48: Medium | H48: Generate /jobs/{metro}/{trade} pages from live data. 60-90d.
A49: Lifecycle email/CRM | B49: Ring 3 | C49: Behind | D49: None (blocked on email provider anyway). | E49: Everyone | F49: Onboarding drips, match alerts, win-back. | G49: Medium | H49: After Brevo key: weekly match digest first. 30-60d.
A50: Infra & cost posture | B50: Ring 3 | C50: Parity | D50: Single Node proc + Turso (free), Render free tier + keep-warm cron, Vercel front door, Docker ready. Boot-crash + event-loop-starvation bugs FIXED this week; healthz self-diagnostics added. $0/mo today. | E50: - | F50: - | G50: Small | H50: Render Starter ($7/mo) kills cold starts at launch. Day 0-30.
A51: Observability | B51: Ring 3 | C51: Partial | D51: /healthz is a real diagnostic: build hash, feature flags (email/sms/google/db/admin), per-port SMTP verdict, exact last email-send error. Diagnosed a platform firewall from it. No error tracker yet. | E51: Sentry-class | F51: Alerting on errors. | G51: Small | H51: Add Sentry free tier. 30d.
...

Sheet 01b - Scorecard Summary
A1: 01b - Scorecard: how much is done, ring by ring
A2: Counts computed live from 01a. Weighted verdict at the bottom.
A4: Ring | B4: Ahead | C4: Parity | D4: Partial | E4: Behind | F4: Total rows | G4: % shipped (Ahead+Parity+Partial)
A5: Ring 1 | B5: =COUNTIFS('01a - Rivet vs Market'!$B$5:$B$52,$A5,'01a - Rivet vs Market'!$C$5:$C$52,B$4) | C5: =COUNTIFS('01a - Rivet vs Market'!$B$5:$B$52,$A5,'01a - Rivet vs Market'!$C$5:$C$52,C$4) | D5: =COUNTIFS('01a - Rivet vs Market'!$B$5:$B$52,$A5,'01a - Rivet vs Market'!$C$5:$C$52,D$4) | E5: =COUNTIFS('01a - Rivet vs Market'!$B$5:$B$52,$A5,'01a - Rivet vs Market'!$C$5:$C$52,E$4) | F5: =SUM(B5:E5) | G5: =IF(F5=0,0,(B5+C5+D5)/F5)
A6: Ring 2 | B6: =COUNTIFS('01a - Rivet vs Market'!$B$5:$B$52,$A6,'01a - Rivet vs Market'!$C$5:$C$52,B$4) | C6: =COUNTIFS('01a - Rivet vs Market'!$B$5:$B$52,$A6,'01a - Rivet vs Market'!$C$5:$C$52,C$4) | D6: =COUNTIFS('01a - Rivet vs Market'!$B$5:$B$52,$A6,'01a - Rivet vs Market'!$C$5:$C$52,D$4) | E6: =COUNTIFS('01a - Rivet vs Market'!$B$5:$B$52,$A6,'01a - Rivet vs Market'!$C$5:$C$52,E$4) | F6: =SUM(B6:E6) | G6: =IF(F6=0,0,(B6+C6+D6)/F6)
A7: Ring 3 | B7: =COUNTIFS('01a - Rivet vs Market'!$B$5:$B$52,$A7,'01a - Rivet vs Market'!$C$5:$C$52,B$4) | C7: =COUNTIFS('01a - Rivet vs Market'!$B$5:$B$52,$A7,'01a - Rivet vs Market'!$C$5:$C$52,C$4) | D7: =COUNTIFS('01a - Rivet vs Market'!$B$5:$B$52,$A7,'01a - Rivet vs Market'!$C$5:$C$52,D$4) | E7: =COUNTIFS('01a - Rivet vs Market'!$B$5:$B$52,$A7,'01a - Rivet vs Market'!$C$5:$C$52,E$4) | F7: =SUM(B7:E7) | G7: =IF(F7=0,0,(B7+C7+D7)/F7)
A8: TOTAL | B8: =SUM(B5:B7) | C8: =SUM(C5:C7) | D8: =SUM(D5:D7) | E8: =SUM(E5:E7) | F8: =SUM(F5:F7) | G8: =IF(F8=0,0,(B8+C8+D8)/F8)
A10: Weighted readiness toward a fundable, launchable startup | B10: ~50% | D10: Ring 1 nearly complete and partly ahead of market; Ring 2 is the work; Ring 3 correctly deferred.
A11: Single most valuable next 90 days | B11: Verification moat + first money | D11: Real credential verification (Sprint 1-2), Checkr, Stripe Connect pilot on shifts in ONE metro.
A12: Cost to keep running today | B12: $0/month | D12: Render free + Turso free + Vercel free + keep-warm cron. First real cost: Render Starter $7/mo + Twilio + domain (~$25/mo all-in).

Sheet 02 - The Three Rings
A1: 02 - The Three Rings: how to think about what to build next
A2: Build from the inside out. Shipping Ring 3 before Ring 2 is how marketplaces die.
A4: Ring | B4: Question it answers | C4: Where Rivet stands (honest) | D4: What "done" looks like
A5: Ring 1 - Core marketplace | B5: Can a worker find real work and an employer find real workers, today, without anyone explaining the app? | C5: ~85% shipped. Auth (email OTP + Google + phone), profiles, matching engine w/ tests, 5-6k REAL ingested jobs, apply/pipeline/messaging/search, shifts board, maps, EN/ES, referrals, community. Several pieces (score transparency, crews, two-sided reputation, live maps) are AHEAD of market. | D5: A worker in Phoenix onboards in <3 min, sees real matched jobs, applies, gets a reply - all self-serve. TRUE today except email delivery key (5-min fix).
A6: Ring 2 - Trust & money | B6: Why would an employer trust these workers, and how does anyone get paid? | C6: ~25% shipped. Reputation system is genuinely ahead (Show-Up Score, Paid-Like-Promised, Safety Pulse). But credential verification is demo-only, no background checks, no payments, no billing, no legal docs. EVERY Critical gap is in this ring. | D6: Top-10 credentials verified against real issuers; Checkr BGC; Stripe Connect moves money on shifts; published ToS/Privacy; pricing live.
A7: Ring 3 - Scale & moat | B7: Why does this win the market instead of staying a nice demo? | C7: ~20% shipped. Live-jobs ingestion engine is a real early moat (nobody else combines aggregated REAL demand with a staffing marketplace at this stage). SEO seeds exist. Everything else correctly deferred. | D7: One metro dense (200+ verified workers, 10+ paying employers), programmatic SEO factory, push notifications driving <15-min shift fills, native app.

Sheet 03 - Competitor Deep-Dives
A1: 03 - Competitor landscape: who we are actually up against
A2: Funding/scale figures are as of early 2026 - re-verify before investor use. Lesson column = what Rivet should copy or dodge.
A4: Company | B4: Model | C4: Scale / funding (early 2026) | D4: Worker side | E4: Employer side | F4: Weakness we can exploit | G4: Lesson for Rivet
A5: Instawork | B5: Flexible-staffing marketplace: hospitality, warehouse, light industrial. W-2 and 1099 options. | C5: 4M+ workers (Instawork; CB Insights cites 10M+), tens of thousands of businesses; $160M total, $60M Series D led by TCV. VERIFIED Jul 2026. | D5: Mobile-first app, InstantPay same-day payout, ratings, shift streaks. | E5: Fill rates + reliability stats, bulk shift posting, integrations. | F5: Generalist: shallow in skilled trades and credentials; workers are interchangeable "pros". | G5: Instant pay + reliability scoring are the retention levers. Our Show-Up Score is the seed of the same system.
A6: Traba | B6: Light-industrial shift marketplace (warehouse, events, food processing, manufacturing). | C6: $43.6M total (seed $3.6M + $20M Series A + $22M A2, Oct 2023) - Founders Fund, Khosla, General Catalyst. Tens of thousands of workers, hundreds of businesses. VERIFIED Jul 2026. | D6: Reliability score, next-day pay, bonuses for streaks. | E6: White-glove ops, vetted worker pools, fill guarantees. | F6: Narrow verticals; high-touch ops model is expensive to scale. | G6: Obsess over fill-rate + reliability as THE metrics. Their playbook validates our shifts board - but only WITH payments.
A7: Wonolo | B7: On-demand blue-collar staffing (1099-heavy). | C7: ~1M+ workers; ~$140M raised. | D7: Simple claim-a-job flow. | E7: Preferred worker pools. | F7: Classification lawsuits; quality complaints; 1099 model under regulatory pressure. | G7: Decide W-2 vs 1099 EARLY with counsel. Do not sleepwalk into misclassification.
A8: BlueRecruit | B8: Direct-hire matching for skilled trades specifically. | C8: Small (seed, ~$5M); niche. | D8: Trade-specific profiles, licenses listed. | E8: Search verified trade candidates. | F8: Tiny liquidity; manual verification does not scale; weak product velocity. | G8: Direct proof our niche (verified TRADES hiring) is underserved. We out-build them on product; must out-execute on verification.
A9: Indeed Flex | B9: Staffing arm of Indeed (W-2 temp). | C9: Backed by Indeed/Recruit Holdings. | D9: W-2 shifts, benefits accrual. | E9: Indeed-scale demand funnel. | F9: Bolt-on to a job board; not trades-focused. | G9: Aggregated demand + staffing hybrid works - our live-jobs ingestion is the same insight at seed stage.
A10: Workrise | B10: Workforce management for energy/skilled trades. | C10: ~$750M raised; pivoted to services/supply chain after marketplace struggles. | D10: Payroll + compliance handled. | E10: Vendor management, payroll. | F10: Lost marketplace focus; cautionary tale. | G10: Focus. Do not become a services company. Software margins only.
A11: GigSmart / Veryable / Bluecrew | B11: Adjacent gig/manufacturing-capacity/W-2 staffing platforms. | C11: Various; smaller. | D11: - | E11: - | F11: Fragmented. | G11: The space is validated but fragmented - a verified-trades wedge with real demand data can win a region.

Sheet 04 - What We Built (Evidence)
A1: 04 - Everything built and verified so far (the receipts)
A2: Every claim in 01a traces to code, a commit, or a live-site probe. This tab is the audit trail.
A4: Date | B4: What shipped | C4: Evidence / commit | D4: Verified how | E4: Status
A5: pre-Jul 2026 | B5: Full core product: auth, worker app (onboarding, matches, applications, credential wallet, portfolio, resume, crews, shifts, agents, coach), employer console (overview, post-job, pipeline, search, analytics, interviews, shortlist, company), matching engine, live ATS ingestion (~40 feeds), maps, EN/ES, community pulse, reviews, referrals, OG images, sitemap, keep-alive cron. | C5: Initial commit ee09640 (squashed history) | D5: Route sweep: every page 200; demo logins work; 8/8 matching tests pass. | E5: LIVE
A6: Jul 4 | B6: Fresh-database boot crash FIXED: createSchema indexed jobs.sector/apply_url/last_seen before migrate() added the columns - every fresh install crashed. Indexes moved after migrations. | C6: 8e3856b | D6: Clean boot on wiped DB; seeded 28k rows; healthz 200. | E6: LIVE
A7: Jul 4 | B7: Event-loop starvation FIXED: file-mode libsql is synchronous; seed/ingest loops froze ALL HTTP for minutes. setImmediate yield per statement (file mode only). | C7: 8e3856b | D7: 36/36 requests <2s during the maintenance window that previously froze the site. | E7: LIVE
A8: Jul 4 | B8: Vercel front door (vercel-proxy/, rewrites all traffic to Render; x-forwarded-host honored so OAuth keeps the public domain). | C8: 8e3856b | D8: Deployed by user; login/signup confirmed working through proxy. | E8: LIVE
A9: Jul 5 | B9: Email OTP verification: email_otp table, users.email_verified, /verify-email flow, enforcement guards on /app + /console. | C9: 3c54eea | D9: Local E2E: signup -> blocked -> wrong code rejected -> correct code -> home. Demo accounts unaffected. | E9: LIVE
A10: Jul 5 | B10: Real OTP delivery only: nodemailer SMTP + Resend + Brevo support, .env loader, .env.example, demo codes removed everywhere; phone login hidden without Twilio. | C10: e7f95f5 | D10: Ran a real local SMTP server; code arrived in the actual email; verified with it. | E10: LIVE
A11: Jul 5 | B11: Security hardening: crypto-grade OTP codes, 5-miss code kill, login lockout 10/15min, signup 20/hr/IP, SMS caps 3/hr/number + 8/hr/IP, resend throttles. | C11: e7f95f5 | D11: Unit tests green; manual cap tests. | E11: LIVE
A12: Jul 5 | B12: Auth UI v2: animated scene (gradient blobs, rising card, shake-on-error), worker/employer role cards, password eye, 6-box OTP with auto-advance/paste/auto-submit, trust badges, reduced-motion. | C12: e7f95f5 | D12: Browser-verified + screenshots; typed a real code -> auto-submitted -> home. | E12: LIVE
A13: Jul 5 | B13: Login accepts email OR mobile number in one field (phone path -> SMS OTP). | C13: 7071823 | D13: Browser test: password hides, button flips to "Text me a code"; email path unchanged. | E13: LIVE
A14: Jul 6 | B14: healthz self-diagnostics: build hash + feature flags (email/sms/google/db) + per-port SMTP verdict; boot log of auth providers. | C14: ac24092, 45b7a56 | D14: Live probe of rivet-crewline.onrender.com/healthz. | E14: LIVE
A15: Jul 6 | B15: Email delivery forensics on Render: IPv6 ENETUNREACH -> forced IPv4 -> port timeout -> dual-port self-heal (465/587) -> VERDICT: Render firewalls ALL outbound SMTP. Automatic fallback SMTP->Brevo/Resend API shipped. Fail-fast sends + on-screen "could not send" banner. | C15: 6d5b214, 5dba153, 76d0473 | D15: Live healthz showed each stage; both ports timeout = platform block, proven. | E15: LIVE (needs BREVO_API_KEY)
... A21: Jul 7 | B21: Production data hygiene: removed 15 test accounts + cascaded data from Turso prod; kept admin + demo accounts. ADMIN_EMAILS live (2 admins). | C21: direct DB op | D21: Post-delete query: only intended accounts remain; healthz: admin 2 configured. | E21: LIVE

Sheet 05 - Market Size & GTM
A1: 05 - Market: why blue-collar hiring, why now, and the wedge
A2: Blue text = assumptions you can change. Black = computed. Figures as of early 2026 knowledge - re-verify before fundraising.
A4: Driver | B4: Value | C4: Source / note
A5: US staffing industry revenue ($B) | B5: 190 | C5: Source: SIA staffing industry forecasts, 2025 estimate.
A6: Share addressable to blue-collar / industrial / trades / care | B6: 0.42 | C6: Source: SIA segment mix (industrial+healthcare+other blue-collar), analyst consensus.
A7: TAM - blue-collar staffing & hiring ($B) | B7: =B5*B6 | C7: Computed.
A8: SAM: our 3 GTM sectors (semiconductor fabs, manufacturing, healthcare support) share | B8: 0.35 | C8: App already tags jobs by these sectors; CHIPS-act fab buildout + care demand.
A9: SAM ($B) | B9: =B7*B8 | C9: Computed.
A10: SOM Year-1: one metro (Phoenix), bottom-up | C10: Bottom-up below is the honest number for a seed pitch.
A11: Verified workers on platform (12-mo goal) | B11: 200 | C11: GTM target - achievable via crew referrals + trade schools.
A12: Direct-hire placements / yr | B12: 150 | C12: Conservative: <1 per verified worker.
A13: Avg placement fee ($) | B13: 1200 | C13: Flat fee well under the 15-20% agency norm - undercut wedge.
A14: Placement revenue ($) | B14: =B12*B13 | C14: Computed.
A15: Shifts filled / week (by month 12) | B15: 300 | C15: Instawork/Traba playbook, single metro.
A16: Avg shift value ($) | B16: 150 | C16: ~8h x $18-20 blended.
A17: Take rate | B17: 0.25 | C17: Market range is 25-40%.
A18: Shift GMV / yr ($) | B18: =B15*52*B16 | C18: Computed.
A19: Shift revenue / yr ($) | B19: =B18*B17 | C19: Computed.
A20: SOM Year-1 revenue ($) | B20: =B14+B19 | C20: Placement + shift take. This is the seed-stage story: ~$0.75M run-rate exiting year 1 in ONE metro.
A22: Why now (the demand tailwind)
A23: * Skilled-trades shortage is structural: 439,000 unfilled construction roles in 2025 (ABC - VERIFIED); 2026 projections 350-500k; ~41% of construction workforce retiring by 2031 (NCCER); shortage is now the #1 cause of project delays (45% of contractors).
A24: * Semiconductor buildout (CHIPS Act): 60-90k fab-adjacent technician shortfall projected by 2030 (SIA/McKinsey) - Phoenix (TSMC/Intel) is ground zero, and the app ALREADY ingests these employers’ live jobs.
A25: * Healthcare support (CNA/caregiver/med-tech): ~800k+ openings/yr, fastest-growing US occupations (BLS) - already a first-class sector in the app.
A26: * Incumbent agencies charge 15-25% placement fees with zero software experience; workers have no portable verified identity. Both sides are ready to switch.
A28: GTM motion (the wedge)
A29: * Phase 0 (now): keep aggregating real jobs -> SEO + worker acquisition for free. Workers come for real jobs, stay for the verified Work Card.
A30: * Phase 1 (90d): Phoenix. Partner with 2-3 trade schools + community colleges for verified-credential workers; sign 10 SMB mechanical/electrical contractors + 1 fab-services vendor as design partners (free, then paid).
A31: * Phase 2 (6mo): turn on payments for shifts; charge placement fees; Show-Up Score + verified credentials become the sales pitch ("hire someone who shows up, licensed - or your fee back").
A32: * Phase 3 (12mo): second metro (Austin or Columbus - fab corridors), native app, W-2 engine decision.

Sheet 06 - Roadmap
A1: 06 - The end-to-end roadmap: from today to a full-fledged startup
A2: Ordered by dependency, not by excitement. Effort assumes 1-2 builders + AI pair. Every row maps back to a gap in 01a.
A4: Horizon | B4: Item | C4: Why (which gap it closes) | D4: Effort | E4: Cost | F4: Definition of done
A5: Day 0 (this week) | B5: ✔ Add BREVO_API_KEY in Render | C5: Email OTP delivery (only gap in Ring-1 auth). Render firewalls SMTP - proven. | D5: 5 min | E5: $0 | F5: DONE Jul 7 — delivery verified live
A6: Day 0 (this week) | B6: Consolidate to ONE GitHub repo (KaryampudiMadhav) on Render + Vercel | C6: Deploys currently need pushing to two repos. | D6: 15 min | E6: $0 | F6: Push once -> both deploy.
A7: Day 0 (this week) | B7: Buy domain; point Vercel + Render; upgrade Render Starter | C7: Brand + kill cold starts. | D7: 1 hr | E7: ~$20/mo | F7: rivetcrewline.com live, no 30s cold start.
A8: Sprint 1 (wk 1-2) | B8: ✔ Credential verification v1: admin review queue + manual state-board lookups (AZ ROC, EPA 608, OSHA cards via issuer portals); "Verified by Rivet" badge only after review | C8: THE MOAT. Homepage promise is currently demo-only (Critical). | D8: 1-2 wk | E8: $0 | F8: DONE Jul 6 (review pipeline live; state-board lookups still to do)
A9: Sprint 1 (wk 1-2) | B9: ✔ Minimal /admin panel (guarded): user lookup, credential queue, job moderation | C9: Ops blocker - ops is SQL console today (High). | D9: 3-4 d | E9: $0 | F9: DONE Jul 6 — live on prod
A10: Sprint 2 (wk 3-4) | B10: Real file uploads (Cloudflare R2 presigned) for credential proofs + portfolio | C10: Verification needs documents (Medium). | D10: 2-3 d | E10: $0 tier | F10: Upload from phone camera works.
A11: Sprint 2 (wk 3-4) | B11: ✔ ToS + Privacy Policy + EEO statement pages; data-deletion endpoint | C11: Legal exposure with real users (Critical). | D11: 2 d + review | E11: ~$500 counsel | F11: DONE Jul 6 (counsel review still pending)
A12: 30-60d | B12: Checkr background-check integration (consent flow, webhook results, employer filter) | C12: Employer trust (Critical). | D12: 1 wk | E12: per-check pass-through | F12: Sandbox E2E; employers see BGC badge.
A13: 30-60d | B13: Web push notifications + Brevo email digests (new matches, application updates, shift alerts) | C13: Fill speed + retention (High). | D13: 1 wk | E13: $0 | F13: Push opt-in >30%; shift alert -> claim loop measured.
A14: 30-60d | B14: Sentry error tracking + uptime alerts | C14: Observability (Medium). | D14: half day | E14: $0 tier | F14: Errors alert before users report.
A15: 60-90d | B15: Stripe Connect Express payouts on the shifts board (one metro pilot); employer billing + 25% take | C15: First revenue (Critical). Validates the Instawork/Traba model on our rails. | D15: 2-3 wk | E15: Stripe fees | F15: A real worker gets a real payout; take-rate revenue in Stripe.
... A22: 6-12mo | B22: Second metro + employer ATS write-back + native apps + seed raise on the numbers above | C22: Scale (Ring 3). | D22: - | E22: - | F22: 2 metros, ~$0.75M+ run-rate, raise-ready metrics dashboard.

Sheet 07 - Risks
A1: 07 - Top risks and how we blunt them
A2: If any of these kills the company, it will be one of the first four.
A4: Risk | B4: Likelihood | C4: Impact | D4: Mitigation
A5: Chicken-and-egg liquidity: workers won’t come without jobs, employers without workers | B5: High | C5: Fatal | D5: Already blunted: live ingested REAL jobs mean workers get value on day 1 with zero employers signed. Focus density in ONE metro/vertical.
A6: Worker misclassification (1099) once payments launch | B6: Medium | C6: Fatal (lawsuits) | D6: Counsel before first payout; consider W-2 via payroll partner; follow Instawork not Wonolo.
A7: Verification promise vs reality gap ("verified" that isn’t) | B7: Medium | C7: Brand-fatal | D7: Ship manual verification BEFORE marketing it; badge only after real review; audit trail.
A8: Free-tier infra fragility (Render cold starts, Turso limits) | B8: Medium | C8: High | D8: Starter plan $7/mo; keep-warm already live; healthz diagnostics already live; Docker escape hatch to any host.
A9: ATS feeds change/block ingestion | B9: Medium | C9: Medium | D9: 40 sources = diversified; dedupe/freshness engine already handles source loss gracefully; add sources monthly.
A10: Incumbent response (Indeed/Instawork moves into verified trades) | B10: Low-Med | C10: High | D10: Speed + niche depth; verified Work Card portability + crew hiring are hard for generalists to copy quickly.
A11: Solo-founder bus factor / velocity | B11: High | C11: High | D11: This week proved velocity (auth+security+UI+diagnostics shipped in days). Codebase is small, documented, AI-friendly. Hire #1: ops/GTM, not eng.
A12: Twilio/SMS costs at scale (esp. India testing) | B12: Low | C12: Low | D12: Rate caps shipped; SMS only for high-intent moments; email/push first.

Sheet 08 - Sources
A1: 08 - Sources & verification status
A2: Every external number in this study, where it came from, and whether it was live-verified on Jul 6, 2026.
A4: Claim | B4: Source | C4: URL | D4: Status
A5: Instawork: $160M total funding, $60M Series D (TCV); 4M+ workers (CB Insights: 10M+) | B5: Staffing Industry Analysts; Crunchbase; CB Insights | C5: staffingindustry.com / crunchbase.com/organization/instawork | D5: VERIFIED Jul 6, 2026
A6: Traba: $43.6M total (seed + Series A + A2); Founders Fund-led; tens of thousands of workers | B6: GlobeNewswire; Contrary Research; Crunchbase | C6: globenewswire.com; research.contrary.com/company/traba | D6: VERIFIED Jul 6, 2026
A7: Construction shortage: 439,000 workers needed 2025; 2026 projections 350-500k; 41% retiring by 2031 | B7: ABC (Associated Builders & Contractors); NCCER; Construction Dive | C7: abc.org/News-Media/News-Releases; constructiondive.com | D7: VERIFIED Jul 6, 2026
A8: US staffing industry ~$190B revenue | B8: SIA (Staffing Industry Analysts) annual forecasts | C8: staffingindustry.com | D8: Early-2026 knowledge - re-verify
A9: Wonolo: ~$140M raised, 1M+ workers; classification pressure | B9: Crunchbase; press coverage | C9: crunchbase.com/organization/wonolo | D9: Early-2026 knowledge - re-verify
A10: Indeed Flex: W-2 staffing arm of Indeed/Recruit Holdings | B10: Indeed Flex site; press | C10: indeedflex.com | D10: Early-2026 knowledge - re-verify
A11: Workrise: ~$750M raised; pivoted toward services/supply chain | B11: Crunchbase; press coverage | C11: crunchbase.com/organization/workrise | D11: Early-2026 knowledge - re-verify
A12: BlueRecruit: seed-stage (~$5M), skilled-trades direct-hire niche | B12: Crunchbase | C12: crunchbase.com/organization/bluerecruit | D12: Early-2026 knowledge - re-verify
A13: Semiconductor fab technician shortfall 60-90k by 2030 | B13: SIA/Oxford Economics chip workforce study; McKinsey | C13: semiconductors.org workforce report | D13: Early-2026 knowledge - re-verify
A14: Healthcare aides: ~800k+ openings/yr, fastest-growing occupations | B14: BLS Occupational Outlook Handbook | C14: bls.gov/ooh | D14: Early-2026 knowledge - re-verify
A15: Welder shortfall 300-400k by late 2020s | B15: American Welding Society (AWS) workforce data | C15: aws.org | D15: Early-2026 knowledge - re-verify
A16: All Rivet x Crewline product claims (tabs 01a, 04) | B16: Direct code inspection, local E2E tests, live probes of rivet-crewline.onrender.com | C16: github.com/KaryampudiMadhav/rivet-crewline | D16: VERIFIED continuously this week

Sheet 09 - KPI Dashboard
A1: 09 - The numbers that matter: KPI targets for the next two quarters
A2: If a metric is not on this list, it is a vanity metric. Review weekly.
A4: Metric | B4: Definition | C4: Today (Jul 2026) | D4: Target @ 90 days | E4: Target @ 6 months
A5: Verified workers | B5: Workers with >=1 credential verified by real review (not demo auto-verify) | C5: 0 (verification is demo) | D5: 200 (Phoenix) | E5: 600
A6: Weekly active workers | B6: Workers with >=1 session/wk | C6: ~0 (pre-launch) | D6: 150 | E6: 500
A7: Paying employers | B7: Employers billed >= $1 | C7: 0 | D7: 3 design partners converting | E7: 15
A8: Fill rate (shifts) | B8: Claimed shifts / posted shifts | C8: n/a (no paid shifts) | D8: 70% | E8: 85% (Instawork-class)
A9: Time-to-fill (jobs) | B9: Post -> first qualified applicant | C9: minutes (seeded pool) | D9: < 24h with real pool | E9: < 4h
A10: Show-Up rate | B10: Showed / claimed (already instrumented in-app!) | C10: instrumented, no volume | D10: > 90% | E10: > 95%
A11: Placement revenue | B11: Direct-hire fees collected | C11: $0 | D11: first paid placement | E11: $15k/mo
A12: Shift take revenue | B12: GMV x take rate | C12: $0 | D12: pilot live | E12: $30k/mo run-rate
A13: Worker D30 retention | B13: Workers active 30d after signup | C13: n/a | D13: 35% | E13: 45%
A14: Verification turnaround | B14: Credential submitted -> verified | C14: n/a | D14: < 48h (manual) | E14: < 24h (80% automated)
A15: Email OTP delivery success | B15: Codes delivered / requested (healthz + Brevo stats) | C15: blocked (needs Brevo key) | D15: > 98% | E15: > 98%
A16: Infra cost / month | B16: All hosting + services | C16: $0 | D16: < $50 | E16: < $300
